<?xml version="1.0" encoding="utf-8"?>
<robot name="ur5_robot">
  <link name="base_link"/>
  <link name="base_link_inertia">
    <visual>
      <origin xyz="0.0 0.0 0.0" rpy="0.0 0.0 3.141592653589793"/>
      <geometry>
        <mesh filename="package://ur_description/meshes/ur5/visual/base.dae.obj"/>
      </geometry>
      <material name="LightGrey">
        <color rgba="0.7 0.7 0.7 1.0"/>
      </material>
    </visual>
    <collision>
      <origin xyz="0.0 0.0 0.0" rpy="0.0 0.0 3.141592653589793"/>
      <geometry>
        <mesh filename="package://ur_description/meshes/ur5/collision/base.stl"/>
      </geometry>
    </collision>
    <inertial>
      <origin xyz="0.0 0.0 0.0" rpy="0.0 0.0 0.0"/>
      <mass value="4.0"/>
      <inertia ixx="0.00443333156" ixy="0.0" ixz="0.0" iyy="0.00443333156" iyz="0.0" izz="0.0072"/>
    </inertial>
  </link>
  <link name="shoulder_link">
    <visual>
      <origin xyz="0.0 0.0 0.0" rpy="0.0 0.0 3.141592653589793"/>
      <geometry>
        <mesh filename="package://ur_description/meshes/ur5/visual/shoulder.dae.obj"/>
      </geometry>
      <material name="LightGrey">
        <color rgba="0.7 0.7 0.7 1.0"/>
      </material>
    </visual>
    <collision>
      <origin xyz="0.0 0.0 0.0" rpy="0.0 0.0 3.141592653589793"/>
      <geometry>
        <mesh filename="package://ur_description/meshes/ur5/collision/shoulder.stl"/>
      </geometry>
    </collision>
    <inertial>
      <origin xyz="0.0 0.0 0.0" rpy="0.0 0.0 0.0"/>
      <mass value="3.7"/>
      <inertia ixx="0.014972352344389999" ixy="0.0" ixz="0.0" iyy="0.014972352344389999" iyz="0.0" izz="0.01040625"/>
    </inertial>
  </link>
  <link name="upper_arm_link">
    <visual>
      <origin xyz="0.0 0.0 0.13585" rpy="1.5707963267948966 0.0 -1.5707963267948966"/>
      <geometry>
        <mesh filename="package://ur_description/meshes/ur5/visual/upperarm.dae.obj"/>
      </geometry>
      <material name="LightGrey">
        <color rgba="0.7 0.7 0.7 1.0"/>
      </material>
    </visual>
    <collision>
      <origin xyz="0.0 0.0 0.13585" rpy="1.5707963267948966 0.0 -1.5707963267948966"/>
      <geometry>
        <mesh filename="package://ur_description/meshes/ur5/collision/upperarm.stl"/>
      </geometry>
    </collision>
    <inertial>
      <origin xyz="-0.2125 0.0 0.136" rpy="0.0 1.5707963267948966 0.0"/>
      <mass value="8.393"/>
      <inertia ixx="0.1338857818623325" ixy="0.0" ixz="0.0" iyy="0.1338857818623325" iyz="0.0" izz="0.0151074"/>
    </inertial>
  </link>
  <link name="forearm_link">
    <visual>
      <origin xyz="0.0 0.0 0.0165" rpy="1.5707963267948966 0.0 -1.5707963267948966"/>
      <geometry>
        <mesh filename="package://ur_description/meshes/ur5/visual/forearm.dae.obj"/>
      </geometry>
      <material name="LightGrey">
        <color rgba="0.7 0.7 0.7 1.0"/>
      </material>
    </visual>
    <collision>
      <origin xyz="0.0 0.0 0.0165" rpy="1.5707963267948966 0.0 -1.5707963267948966"/>
      <geometry>
        <mesh filename="package://ur_description/meshes/ur5/collision/forearm.stl"/>
      </geometry>
    </collision>
    <inertial>
      <origin xyz="-0.196125 0.0 0.0165" rpy="0.0 1.5707963267948966 0.0"/>
      <mass value="2.275"/>
      <inertia ixx="0.03121679102890359" ixy="0.0" ixz="0.0" iyy="0.03121679102890359" iyz="0.0" izz="0.004095"/>
    </inertial>
  </link>
  <link name="wrist_1_link">
    <visual>
      <origin xyz="0.0 0.0 -0.093" rpy="1.5707963267948966 0.0 0.0"/>
      <geometry>
        <mesh filename="package://ur_description/meshes/ur5/visual/wrist1.dae.obj"/>
      </geometry>
      <material name="LightGrey">
        <color rgba="0.7 0.7 0.7 1.0"/>
      </material>
    </visual>
    <collision>
      <origin xyz="0.0 0.0 -0.093" rpy="1.5707963267948966 0.0 0.0"/>
      <geometry>
        <mesh filename="package://ur_description/meshes/ur5/collision/wrist1.stl"/>
      </geometry>
    </collision>
    <inertial>
      <origin xyz="0.0 0.0 0.0" rpy="0.0 0.0 0.0"/>
      <mass value="1.219"/>
      <inertia ixx="0.0020138887777775" ixy="0.0" ixz="0.0" iyy="0.0020138887777775" iyz="0.0" izz="0.0021942"/>
    </inertial>
  </link>
  <link name="wrist_2_link">
    <visual>
      <origin xyz="0.0 0.0 -0.095" rpy="0.0 0.0 0.0"/>
      <geometry>
        <mesh filename="package://ur_description/meshes/ur5/visual/wrist2.dae.obj"/>
      </geometry>
      <material name="LightGrey">
        <color rgba="0.7 0.7 0.7 1.0"/>
      </material>
    </visual>
    <collision>
      <origin xyz="0.0 0.0 -0.095" rpy="0.0 0.0 0.0"/>
      <geometry>
        <mesh filename="package://ur_description/meshes/ur5/collision/wrist2.stl"/>
      </geometry>
    </collision>
    <inertial>
      <origin xyz="0.0 0.0 0.0" rpy="0.0 0.0 0.0"/>
      <mass value="1.219"/>
      <inertia ixx="0.0018310388509175" ixy="0.0" ixz="0.0" iyy="0.0018310388509175" iyz="0.0" izz="0.0021942"/>
    </inertial>
  </link>
  <link name="wrist_3_link">
    <visual>
      <origin xyz="0.0 0.0 -0.0818" rpy="1.5707963267948966 0.0 0.0"/>
      <geometry>
        <mesh filename="package://ur_description/meshes/ur5/visual/wrist3.dae.obj"/>
      </geometry>
      <material name="LightGrey">
        <color rgba="0.7 0.7 0.7 1.0"/>
      </material>
    </visual>
    <collision>
      <origin xyz="0.0 0.0 -0.0818" rpy="1.5707963267948966 0.0 0.0"/>
      <geometry>
        <mesh filename="package://ur_description/meshes/ur5/collision/wrist3.stl"/>
      </geometry>
    </collision>
    <inertial>
      <origin xyz="0.0 0.0 -0.01525" rpy="0.0 0.0 0.0"/>
      <mass value="0.1879"/>
      <inertia ixx="8.062472608343e-05" ixy="0.0" ixz="0.0" iyy="8.062472608343e-05" iyz="0.0" izz="0.0001321171875"/>
    </inertial>
  </link>
  <link name="base"/>
  <link name="flange"/>
  <link name="tool0"/>
  <joint name="base_link-base_link_inertia" type="fixed">
    <parent link="base_link"/>
    <child link="base_link_inertia"/>
    <axis xyz="1.0 0.0 0.0"/>
    <origin xyz="0.0 0.0 0.0" rpy="0.0 0.0 3.141592653589793"/>
  </joint>
  <joint name="shoulder_pan_joint" type="revolute">
    <parent link="base_link_inertia"/>
    <child link="shoulder_link"/>
    <axis xyz="0.0 0.0 1.0"/>
    <dynamics damping="0.0" friction="0.0"/>
    <limit lower="-6.283185307179586" upper="6.283185307179586" effort="150.0" velocity="3.141592653589793"/>
    <origin xyz="0.0 0.0 0.089159" rpy="0.0 0.0 0.0"/>
  </joint>
  <joint name="shoulder_lift_joint" type="revolute">
    <parent link="shoulder_link"/>
    <child link="upper_arm_link"/>
    <axis xyz="0.0 0.0 1.0"/>
    <dynamics damping="0.0" friction="0.0"/>
    <limit lower="-6.283185307179586" upper="6.283185307179586" effort="150.0" velocity="3.141592653589793"/>
    <origin xyz="0.0 0.0 0.0" rpy="1.570796327 0.0 0.0"/>
  </joint>
  <joint name="elbow_joint" type="revolute">
    <parent link="upper_arm_link"/>
    <child link="forearm_link"/>
    <axis xyz="0.0 0.0 1.0"/>
    <dynamics damping="0.0" friction="0.0"/>
    <limit lower="-3.141592653589793" upper="3.141592653589793" effort="150.0" velocity="3.141592653589793"/>
    <origin xyz="-0.425 0.0 0.0" rpy="0.0 0.0 0.0"/>
  </joint>
  <joint name="wrist_1_joint" type="revolute">
    <parent link="forearm_link"/>
    <child link="wrist_1_link"/>
    <axis xyz="0.0 0.0 1.0"/>
    <dynamics damping="0.0" friction="0.0"/>
    <limit lower="-6.283185307179586" upper="6.283185307179586" effort="28.0" velocity="3.141592653589793"/>
    <origin xyz="-0.39225 0.0 0.10915" rpy="0.0 0.0 0.0"/>
  </joint>
  <joint name="wrist_2_joint" type="revolute">
    <parent link="wrist_1_link"/>
    <child link="wrist_2_link"/>
    <axis xyz="0.0 0.0 1.0"/>
    <dynamics damping="0.0" friction="0.0"/>
    <limit lower="-6.283185307179586" upper="6.283185307179586" effort="28.0" velocity="3.141592653589793"/>
    <origin xyz="0.0 -0.09465 -1.941303950897609e-11" rpy="1.570796327 0.0 0.0"/>
  </joint>
  <joint name="wrist_3_joint" type="revolute">
    <parent link="wrist_2_link"/>
    <child link="wrist_3_link"/>
    <axis xyz="0.0 0.0 1.0"/>
    <dynamics damping="0.0" friction="0.0"/>
    <limit lower="-6.283185307179586" upper="6.283185307179586" effort="28.0" velocity="3.141592653589793"/>
    <origin xyz="0.0 0.0823 -1.688001216681175e-11" rpy="-1.5707963270000003 1.2246467991473532e-16 -1.2246467991473532e-16"/>
  </joint>
  <joint name="base_link-base_fixed_joint" type="fixed">
    <parent link="base_link"/>
    <child link="base"/>
    <axis xyz="1.0 0.0 0.0"/>
    <origin xyz="0.0 0.0 0.0" rpy="0.0 0.0 3.141592653589793"/>
  </joint>
  <joint name="wrist_3-flange" type="fixed">
    <parent link="wrist_3_link"/>
    <child link="flange"/>
    <axis xyz="1.0 0.0 0.0"/>
    <origin xyz="0.0 0.0 0.0" rpy="-1.5707963267948966 -1.5707963267948966 0.0"/>
  </joint>
  <joint name="flange-tool0" type="fixed">
    <parent link="flange"/>
    <child link="tool0"/>
    <axis xyz="1.0 0.0 0.0"/>
    <origin xyz="0.0 0.0 0.0" rpy="1.5707963267948966 0.0 1.5707963267948966"/>
  </joint>
  <transmission name="wrist_3_trans">
    <type>transmission_interface/SimpleTransmission</type>
    <joint name="wrist_3_joint">
      <hardwareInterface>hardware_interface/PositionJointInterface</hardwareInterface>
    </joint>
    <actuator name="wrist_3_motor">
      <mechanicalReduction>1</mechanicalReduction>
    </actuator>
  </transmission>
</robot>
