<?xml version="1.0" ?>
<!-- =================================================================================== -->
<!-- |    This document was autogenerated by xacro from rfl.xacro                      | -->
<!-- |    EDITING THIS FILE BY HAND IS NOT RECOMMENDED                                 | -->
<!-- =================================================================================== -->
<robot name="rfl" xmlns:xacro="http://ros.org/wiki/xacro">
  <!-- Conversion were obtained from http://www.e-paint.co.uk/Lab_values.asp
       unless otherwise stated. -->
  <!-- Conversion were obtained from http://www.e-paint.co.uk/Lab_values.asp
       unless otherwise stated. -->
  <!-- Conversion were obtained from http://www.e-paint.co.uk/Lab_values.asp
       unless otherwise stated. -->
  <!-- Conversion were obtained from http://www.e-paint.co.uk/Lab_values.asp
       unless otherwise stated. -->
  <link name="world">
    <visual>
      <origin rpy="0.0 0.0 0.0" xyz="0.0 0.0 0.0"/>
      <geometry>
        <mesh filename="package://rfl_description/meshes/visual/rfl_floor_and_columns.stl"/>
      </geometry>
    </visual>
    <collision>
      <origin rpy="0.0 0.0 0.0" xyz="0.0 0.0 0.0"/>
      <geometry>
        <mesh filename="package://rfl_description/meshes/collision/rfl_floor_and_columns.stl"/>
      </geometry>
    </collision>
  </link>
  <joint name="world_joint" type="fixed">
    <parent link="world"/>
    <child link="x_rail"/>
    <origin rpy="0.0 0.0 0.0" xyz="0.0 0.0 0.0"/>
  </joint>
  <link name="x_rail">
    <visual>
      <origin rpy="0 0 0" xyz="0 0 0"/>
      <geometry>
        <mesh filename="package://rfl_description/meshes/visual/x_rail.stl"/>
      </geometry>
      <material name="">
        <color rgba="0.9254902 0.9254902 0.9058824 1"/>
      </material>
    </visual>
    <collision>
      <origin rpy="0 0 0" xyz="0 0 0"/>
      <geometry>
        <mesh filename="package://rfl_description/meshes/collision/x_rail.stl"/>
      </geometry>
    </collision>
  </link>
  <joint name="bridge1_joint_EA_X" type="prismatic">
    <parent link="x_rail"/>
    <child link="bridge1"/>
    <origin rpy="0 0 0" xyz="0 0 0"/>
    <axis xyz="1 0 0"/>
    <limit effort="100000" lower="0.0" upper="37.206" velocity="2.618"/>
    <dynamics damping="0.2" friction="0"/>
  </joint>
  <link name="bridge1">
    <inertial>
      <origin xyz="0.0 0.0 0.0"/>
      <mass value="120.00000"/>
      <inertia ixx="-4.98000" ixy="-0.00000" ixz="2.70000" iyy="-5.95200" iyz="-0.00000" izz="0.82800"/>
    </inertial>
    <visual>
      <origin rpy="0 0 0.0" xyz="0.0 0.0 0.0"/>
      <geometry>
        <mesh filename="package://rfl_description/meshes/visual/y_gantry.stl"/>
      </geometry>
      <material name="">
        <color rgba="0.9254902 0.9254902 0.9058824 1"/>
      </material>
    </visual>
    <collision>
      <origin rpy="0 0 0.0" xyz="0.0 0.0 0.0"/>
      <geometry>
        <mesh filename="package://rfl_description/meshes/collision/y_gantry.stl"/>
      </geometry>
    </collision>
  </link>
  <joint name="robot11_joint_EA_Y" type="prismatic">
    <parent link="bridge1"/>
    <child link="robot11_xy_cart"/>
    <origin rpy="0 0 0 " xyz="0 0 0"/>
    <axis xyz="0 -1 0"/>
    <limit effort="100000" lower="-9.65" upper="0.0" velocity="2.618"/>
    <dynamics damping="0.2" friction="0"/>
  </joint>
  <link name="robot11_xy_cart">
    <inertial>
      <origin xyz="0.0 0.0 0.0"/>
      <mass value="120.00000"/>
      <inertia ixx="-4.98000" ixy="-0.00000" ixz="2.70000" iyy="-5.95200" iyz="-0.00000" izz="0.82800"/>
    </inertial>
    <visual>
      <origin rpy="0 0 0.0" xyz="0.0 0.0 0.0"/>
      <geometry>
        <mesh filename="package://rfl_description/meshes/visual/group1_xy_cart.stl"/>
      </geometry>
      <material name="">
        <color rgba="0.9254902 0.9254902 0.9058824 1"/>
      </material>
    </visual>
    <collision>
      <origin rpy="0 0 0.0" xyz="0.0 0.0 0.0"/>
      <geometry>
        <mesh filename="package://rfl_description/meshes/collision/group1_xy_cart.stl"/>
      </geometry>
    </collision>
  </link>
  <joint name="robot11_joint_EA_Z" type="prismatic">
    <parent link="robot11_xy_cart"/>
    <child link="robot11_base"/>
    <origin rpy="0 0 0 " xyz="0 0 0"/>
    <axis xyz="0 0 -1"/>
    <limit effort="100000" lower="-4.915" upper="-1.005" velocity="2.618"/>
    <dynamics damping="0.2" friction="0"/>
  </joint>
  <link name="robot11_base">
    <inertial>
      <origin xyz="0.0 0.0 0.0"/>
      <mass value="120.00000"/>
      <inertia ixx="-4.98000" ixy="-0.00000" ixz="2.70000" iyy="-5.95200" iyz="-0.00000" izz="0.82800"/>
    </inertial>
    <visual>
      <origin rpy="0 0 0.0" xyz="0.0 0.0 0.0"/>
      <geometry>
        <mesh filename="package://rfl_description/meshes/visual/group1_z_axis.stl"/>
      </geometry>
      <material name="">
        <color rgba="0.9254902 0.9254902 0.9058824 1"/>
      </material>
    </visual>
    <collision>
      <origin rpy="0 0 0.0" xyz="0.0 0.0 0.0"/>
      <geometry>
        <mesh filename="package://rfl_description/meshes/collision/group1_z_axis.stl"/>
      </geometry>
    </collision>
  </link>
  <joint name="robot11_joint_0" type="fixed">
    <parent link="robot11_base"/>
    <child link="robot11_base_link"/>
    <origin rpy="3.14159265359 0 0.0" xyz="0 0 0"/>
    <dynamics damping="0.2" friction="0"/>
  </joint>
  <!-- link list -->
  <link name="robot11_base_link">
    <inertial>
      <origin xyz="0.0 0.0 0.0"/>
      <mass value="120.00000"/>
      <inertia ixx="-4.98000" ixy="0.00000" ixz="2.70000" iyy="-5.95200" iyz="0.00000" izz="0.82800"/>
    </inertial>
    <visual>
      <geometry>
        <mesh filename="package://abb_irb4600_40_255/meshes/visual/base_link.stl"/>
      </geometry>
      <material name="">
        <color rgba="0.7725490 0.7803922 0.7686275 1"/>
      </material>
    </visual>
    <collision>
      <geometry>
        <mesh filename="package://abb_irb4600_40_255/meshes/collision/base_link.stl"/>
      </geometry>
    </collision>
  </link>
  <link name="robot11_link_1">
    <inertial>
      <origin xyz="0.18000 0.00000 0.50000"/>
      <mass value="120.00000"/>
      <inertia ixx="-4.98000" ixy="0.00000" ixz="2.70000" iyy="-5.95200" iyz="0.00000" izz="0.82800"/>
    </inertial>
    <visual>
      <geometry>
        <mesh filename="package://abb_irb4600_40_255/meshes/visual/link_1.stl"/>
      </geometry>
      <material name="">
        <color rgba="0.7725490 0.7803922 0.7686275 1"/>
      </material>
    </visual>
    <collision>
      <geometry>
        <mesh filename="package://abb_irb4600_40_255/meshes/collision/link_1.stl"/>
      </geometry>
    </collision>
  </link>
  <link name="robot11_link_2">
    <inertial>
      <origin xyz="0.94000 0.08000 -0.34000"/>
      <mass value="120.00000"/>
      <inertia ixx="-2.96000" ixy="2.25600" ixz="-9.58800" iyy="-18.72601" iyz="-0.81600" izz="-14.95000"/>
    </inertial>
    <visual>
      <geometry>
        <mesh filename="package://abb_irb4600_40_255/meshes/visual/link_2.stl"/>
      </geometry>
      <material name="">
        <color rgba="0.7725490 0.7803922 0.7686275 1"/>
      </material>
    </visual>
    <collision>
      <geometry>
        <mesh filename="package://abb_irb4600_40_255/meshes/collision/link_2.stl"/>
      </geometry>
    </collision>
  </link>
  <link name="robot11_link_3">
    <inertial>
      <origin xyz="0.07000 -0.26600 0.08800"/>
      <mass value="120.00000"/>
      <inertia ixx="1.34500" ixy="0.55860" ixz="0.18480" iyy="4.65068" iyz="-0.70224" izz="2.76032"/>
    </inertial>
    <visual>
      <geometry>
        <mesh filename="package://abb_irb4600_40_255/meshes/visual/link_3.stl"/>
      </geometry>
      <material name="">
        <color rgba="0.7725490 0.7803922 0.7686275 1"/>
      </material>
    </visual>
    <collision>
      <geometry>
        <mesh filename="package://abb_irb4600_40_255/meshes/collision/link_3.stl"/>
      </geometry>
    </collision>
  </link>
  <link name="robot11_link_4">
    <inertial>
      <origin xyz="0.00000 0.00000 1.00000"/>
      <mass value="40.00000"/>
      <inertia ixx="-8.00000" ixy="0.00000" ixz="0.00000" iyy="-8.00000" iyz="0.00000" izz="0.48200"/>
    </inertial>
    <visual>
      <geometry>
        <mesh filename="package://abb_irb4600_40_255/meshes/visual/link_4.stl"/>
      </geometry>
      <material name="">
        <color rgba="0.7725490 0.7803922 0.7686275 1"/>
      </material>
    </visual>
    <collision>
      <geometry>
        <mesh filename="package://abb_irb4600_40_255/meshes/collision/link_4.stl"/>
      </geometry>
    </collision>
  </link>
  <link name="robot11_link_5">
    <inertial>
      <origin xyz="0.14000 0.00000 0.00000"/>
      <mass value="10.00000"/>
      <inertia ixx="0.04000" ixy="0.00000" ixz="0.00000" iyy="-0.00900" iyz="0.00000" izz="-0.00400"/>
    </inertial>
    <visual>
      <geometry>
        <mesh filename="package://abb_irb4600_40_255/meshes/visual/link_5.stl"/>
      </geometry>
      <material name="">
        <color rgba="0.7725490 0.7803922 0.7686275 1"/>
      </material>
    </visual>
    <collision>
      <geometry>
        <mesh filename="package://abb_irb4600_40_255/meshes/collision/link_5.stl"/>
      </geometry>
    </collision>
  </link>
  <link name="robot11_link_6">
    <inertial>
      <origin xyz="0.08100 -0.09100 0.33200"/>
      <mass value="5.00000"/>
      <inertia ixx="-0.29652" ixy="-0.03686" ixz="0.09396" iyy="-0.28792" iyz="-0.10556" izz="-0.04621"/>
    </inertial>
    <visual>
      <geometry>
        <mesh filename="package://abb_irb4600_40_255/meshes/visual/link_6.stl"/>
      </geometry>
      <material name="">
        <color rgba="0.1882353 0.1960784 0.2039216 1"/>
      </material>
    </visual>
    <collision>
      <geometry>
        <mesh filename="package://abb_irb4600_40_255/meshes/collision/link_6.stl"/>
      </geometry>
    </collision>
  </link>
  <link name="robot11_tool0"/>
  <!-- end of link list -->
  <!-- joint list -->
  <joint name="robot11_joint_1" type="revolute">
    <parent link="robot11_base_link"/>
    <child link="robot11_link_1"/>
    <origin rpy="0 0 0 " xyz="0 0 0"/>
    <axis xyz="0 0 1"/>
    <!-- (-180 to 180) -->
    <limit effort="100000" lower="-3.14159265359" upper="3.14159265359" velocity="2.618"/>
    <dynamics damping="0.2" friction="0"/>
  </joint>
  <joint name="robot11_joint_2" type="revolute">
    <parent link="robot11_link_1"/>
    <child link="robot11_link_2"/>
    <origin rpy="0 0 0 " xyz="0.175 0 0.495"/>
    <axis xyz="0 1 0"/>
    <!-- (-90 to 150) -->
    <limit effort="100000" lower="-1.57079632679" upper="2.61799387799" velocity="2.618"/>
    <dynamics damping="0.2" friction="0"/>
  </joint>
  <joint name="robot11_joint_3" type="revolute">
    <parent link="robot11_link_2"/>
    <child link="robot11_link_3"/>
    <origin rpy="0 0 0 " xyz="0 0 1.095"/>
    <axis xyz="0 1 0"/>
    <!-- (-180 to 75) -->
    <limit effort="100000" lower="-3.14159265359" upper="1.308996939" velocity="2.618"/>
    <dynamics damping="0.2" friction="0"/>
  </joint>
  <joint name="robot11_joint_4" type="revolute">
    <parent link="robot11_link_3"/>
    <child link="robot11_link_4"/>
    <origin rpy="0 0 0 " xyz="0.331 0 0.175"/>
    <axis xyz="1 0 0"/>
    <!-- (-400 to 400) -->
    <limit effort="10000" lower="-6.98131700798" upper="6.98131700798" velocity="6.2832"/>
    <dynamics damping="0.2" friction="0"/>
  </joint>
  <joint name="robot11_joint_5" type="revolute">
    <parent link="robot11_link_4"/>
    <child link="robot11_link_5"/>
    <origin rpy="0 0 0 " xyz="0.939 0 0"/>
    <axis xyz="0 1 0"/>
    <!-- (-125 to 120) -->
    <limit effort="100000" lower="-2.18166" upper="2.18166156499" velocity="6.2832"/>
    <dynamics damping="0.2" friction="0"/>
  </joint>
  <joint name="robot11_joint_6" type="revolute">
    <parent link="robot11_link_5"/>
    <child link="robot11_link_6"/>
    <origin rpy="0 1.57079632679 0" xyz="0.135 0 0"/>
    <axis xyz="0 0 1"/>
    <!-- (-400 to 400) -->
    <limit effort="100000" lower="-6.98131700798" upper="6.98131700798" velocity="7.854"/>
    <dynamics damping="0.2" friction="0"/>
  </joint>
  <joint name="robot11_joint_6-tool0" type="fixed">
    <parent link="robot11_link_6"/>
    <child link="robot11_tool0"/>
    <origin rpy="0 0 0" xyz="0 0 0"/>
  </joint>
  <!-- end of joint list -->
  <!-- ROS base_link to ABB World Coordinates transform >
    <link name="${prefix}base" />
    <joint name="${prefix}base_link-base" type="fixed">
      <origin xyz="0 0 0" rpy="0 0 0"/>
      <parent link="${prefix}base_link"/>
      <child link="${prefix}base"/>
    </joint-->
  <joint name="robot12_joint_EA_Y" type="prismatic">
    <parent link="bridge1"/>
    <child link="robot12_xy_cart"/>
    <origin rpy="0 0 0 " xyz="0 0 0"/>
    <axis xyz="0 -1 0"/>
    <limit effort="100000" lower="-12.237" upper="-2.587" velocity="2.618"/>
    <dynamics damping="0.2" friction="0"/>
  </joint>
  <link name="robot12_xy_cart">
    <inertial>
      <origin xyz="0.0 0.0 0.0"/>
      <mass value="120.00000"/>
      <inertia ixx="-4.98000" ixy="-0.00000" ixz="2.70000" iyy="-5.95200" iyz="-0.00000" izz="0.82800"/>
    </inertial>
    <visual>
      <origin rpy="0 0 0.0" xyz="0.0 0.0 0.0"/>
      <geometry>
        <mesh filename="package://rfl_description/meshes/visual/group2_xy_cart.stl"/>
      </geometry>
      <material name="">
        <color rgba="0.9254902 0.9254902 0.9058824 1"/>
      </material>
    </visual>
    <collision>
      <origin rpy="0 0 0.0" xyz="0.0 0.0 0.0"/>
      <geometry>
        <mesh filename="package://rfl_description/meshes/collision/group2_xy_cart.stl"/>
      </geometry>
    </collision>
  </link>
  <joint name="robot12_joint_EA_Z" type="prismatic">
    <parent link="robot12_xy_cart"/>
    <child link="robot12_base"/>
    <origin rpy="0 0 0 " xyz="0 0 0"/>
    <axis xyz="0 0 -1"/>
    <limit effort="100000" lower="-4.915" upper="-1.005" velocity="2.618"/>
    <dynamics damping="0.2" friction="0"/>
  </joint>
  <link name="robot12_base">
    <inertial>
      <origin xyz="0.0 0.0 0.0"/>
      <mass value="120.00000"/>
      <inertia ixx="-4.98000" ixy="-0.00000" ixz="2.70000" iyy="-5.95200" iyz="-0.00000" izz="0.82800"/>
    </inertial>
    <visual>
      <origin rpy="0 0 0.0" xyz="0.0 0.0 0.0"/>
      <geometry>
        <mesh filename="package://rfl_description/meshes/visual/group2_z_axis.stl"/>
      </geometry>
      <material name="">
        <color rgba="0.9254902 0.9254902 0.9058824 1"/>
      </material>
    </visual>
    <collision>
      <origin rpy="0 0 0.0" xyz="0.0 0.0 0.0"/>
      <geometry>
        <mesh filename="package://rfl_description/meshes/collision/group2_z_axis.stl"/>
      </geometry>
    </collision>
  </link>
  <joint name="robot12_joint_0" type="fixed">
    <parent link="robot12_base"/>
    <child link="robot12_base_link"/>
    <origin rpy="3.14159265359 0 0.0" xyz="0 0 0"/>
    <dynamics damping="0.2" friction="0"/>
  </joint>
  <!-- link list -->
  <link name="robot12_base_link">
    <inertial>
      <origin xyz="0.0 0.0 0.0"/>
      <mass value="120.00000"/>
      <inertia ixx="-4.98000" ixy="0.00000" ixz="2.70000" iyy="-5.95200" iyz="0.00000" izz="0.82800"/>
    </inertial>
    <visual>
      <geometry>
        <mesh filename="package://abb_irb4600_40_255/meshes/visual/base_link.stl"/>
      </geometry>
      <material name="">
        <color rgba="0.7725490 0.7803922 0.7686275 1"/>
      </material>
    </visual>
    <collision>
      <geometry>
        <mesh filename="package://abb_irb4600_40_255/meshes/collision/base_link.stl"/>
      </geometry>
    </collision>
  </link>
  <link name="robot12_link_1">
    <inertial>
      <origin xyz="0.18000 0.00000 0.50000"/>
      <mass value="120.00000"/>
      <inertia ixx="-4.98000" ixy="0.00000" ixz="2.70000" iyy="-5.95200" iyz="0.00000" izz="0.82800"/>
    </inertial>
    <visual>
      <geometry>
        <mesh filename="package://abb_irb4600_40_255/meshes/visual/link_1.stl"/>
      </geometry>
      <material name="">
        <color rgba="0.7725490 0.7803922 0.7686275 1"/>
      </material>
    </visual>
    <collision>
      <geometry>
        <mesh filename="package://abb_irb4600_40_255/meshes/collision/link_1.stl"/>
      </geometry>
    </collision>
  </link>
  <link name="robot12_link_2">
    <inertial>
      <origin xyz="0.94000 0.08000 -0.34000"/>
      <mass value="120.00000"/>
      <inertia ixx="-2.96000" ixy="2.25600" ixz="-9.58800" iyy="-18.72601" iyz="-0.81600" izz="-14.95000"/>
    </inertial>
    <visual>
      <geometry>
        <mesh filename="package://abb_irb4600_40_255/meshes/visual/link_2.stl"/>
      </geometry>
      <material name="">
        <color rgba="0.7725490 0.7803922 0.7686275 1"/>
      </material>
    </visual>
    <collision>
      <geometry>
        <mesh filename="package://abb_irb4600_40_255/meshes/collision/link_2.stl"/>
      </geometry>
    </collision>
  </link>
  <link name="robot12_link_3">
    <inertial>
      <origin xyz="0.07000 -0.26600 0.08800"/>
      <mass value="120.00000"/>
      <inertia ixx="1.34500" ixy="0.55860" ixz="0.18480" iyy="4.65068" iyz="-0.70224" izz="2.76032"/>
    </inertial>
    <visual>
      <geometry>
        <mesh filename="package://abb_irb4600_40_255/meshes/visual/link_3.stl"/>
      </geometry>
      <material name="">
        <color rgba="0.7725490 0.7803922 0.7686275 1"/>
      </material>
    </visual>
    <collision>
      <geometry>
        <mesh filename="package://abb_irb4600_40_255/meshes/collision/link_3.stl"/>
      </geometry>
    </collision>
  </link>
  <link name="robot12_link_4">
    <inertial>
      <origin xyz="0.00000 0.00000 1.00000"/>
      <mass value="40.00000"/>
      <inertia ixx="-8.00000" ixy="0.00000" ixz="0.00000" iyy="-8.00000" iyz="0.00000" izz="0.48200"/>
    </inertial>
    <visual>
      <geometry>
        <mesh filename="package://abb_irb4600_40_255/meshes/visual/link_4.stl"/>
      </geometry>
      <material name="">
        <color rgba="0.7725490 0.7803922 0.7686275 1"/>
      </material>
    </visual>
    <collision>
      <geometry>
        <mesh filename="package://abb_irb4600_40_255/meshes/collision/link_4.stl"/>
      </geometry>
    </collision>
  </link>
  <link name="robot12_link_5">
    <inertial>
      <origin xyz="0.14000 0.00000 0.00000"/>
      <mass value="10.00000"/>
      <inertia ixx="0.04000" ixy="0.00000" ixz="0.00000" iyy="-0.00900" iyz="0.00000" izz="-0.00400"/>
    </inertial>
    <visual>
      <geometry>
        <mesh filename="package://abb_irb4600_40_255/meshes/visual/link_5.stl"/>
      </geometry>
      <material name="">
        <color rgba="0.7725490 0.7803922 0.7686275 1"/>
      </material>
    </visual>
    <collision>
      <geometry>
        <mesh filename="package://abb_irb4600_40_255/meshes/collision/link_5.stl"/>
      </geometry>
    </collision>
  </link>
  <link name="robot12_link_6">
    <inertial>
      <origin xyz="0.08100 -0.09100 0.33200"/>
      <mass value="5.00000"/>
      <inertia ixx="-0.29652" ixy="-0.03686" ixz="0.09396" iyy="-0.28792" iyz="-0.10556" izz="-0.04621"/>
    </inertial>
    <visual>
      <geometry>
        <mesh filename="package://abb_irb4600_40_255/meshes/visual/link_6.stl"/>
      </geometry>
      <material name="">
        <color rgba="0.1882353 0.1960784 0.2039216 1"/>
      </material>
    </visual>
    <collision>
      <geometry>
        <mesh filename="package://abb_irb4600_40_255/meshes/collision/link_6.stl"/>
      </geometry>
    </collision>
  </link>
  <link name="robot12_tool0"/>
  <!-- end of link list -->
  <!-- joint list -->
  <joint name="robot12_joint_1" type="revolute">
    <parent link="robot12_base_link"/>
    <child link="robot12_link_1"/>
    <origin rpy="0 0 0 " xyz="0 0 0"/>
    <axis xyz="0 0 1"/>
    <!-- (-180 to 180) -->
    <limit effort="100000" lower="-3.14159265359" upper="3.14159265359" velocity="2.618"/>
    <dynamics damping="0.2" friction="0"/>
  </joint>
  <joint name="robot12_joint_2" type="revolute">
    <parent link="robot12_link_1"/>
    <child link="robot12_link_2"/>
    <origin rpy="0 0 0 " xyz="0.175 0 0.495"/>
    <axis xyz="0 1 0"/>
    <!-- (-90 to 150) -->
    <limit effort="100000" lower="-1.57079632679" upper="2.61799387799" velocity="2.618"/>
    <dynamics damping="0.2" friction="0"/>
  </joint>
  <joint name="robot12_joint_3" type="revolute">
    <parent link="robot12_link_2"/>
    <child link="robot12_link_3"/>
    <origin rpy="0 0 0 " xyz="0 0 1.095"/>
    <axis xyz="0 1 0"/>
    <!-- (-180 to 75) -->
    <limit effort="100000" lower="-3.14159265359" upper="1.308996939" velocity="2.618"/>
    <dynamics damping="0.2" friction="0"/>
  </joint>
  <joint name="robot12_joint_4" type="revolute">
    <parent link="robot12_link_3"/>
    <child link="robot12_link_4"/>
    <origin rpy="0 0 0 " xyz="0.331 0 0.175"/>
    <axis xyz="1 0 0"/>
    <!-- (-400 to 400) -->
    <limit effort="10000" lower="-6.98131700798" upper="6.98131700798" velocity="6.2832"/>
    <dynamics damping="0.2" friction="0"/>
  </joint>
  <joint name="robot12_joint_5" type="revolute">
    <parent link="robot12_link_4"/>
    <child link="robot12_link_5"/>
    <origin rpy="0 0 0 " xyz="0.939 0 0"/>
    <axis xyz="0 1 0"/>
    <!-- (-125 to 120) -->
    <limit effort="100000" lower="-2.18166" upper="2.18166156499" velocity="6.2832"/>
    <dynamics damping="0.2" friction="0"/>
  </joint>
  <joint name="robot12_joint_6" type="revolute">
    <parent link="robot12_link_5"/>
    <child link="robot12_link_6"/>
    <origin rpy="0 1.57079632679 0" xyz="0.135 0 0"/>
    <axis xyz="0 0 1"/>
    <!-- (-400 to 400) -->
    <limit effort="100000" lower="-6.98131700798" upper="6.98131700798" velocity="7.854"/>
    <dynamics damping="0.2" friction="0"/>
  </joint>
  <joint name="robot12_joint_6-tool0" type="fixed">
    <parent link="robot12_link_6"/>
    <child link="robot12_tool0"/>
    <origin rpy="0 0 0" xyz="0 0 0"/>
  </joint>
  <!-- end of joint list -->
  <!-- ROS base_link to ABB World Coordinates transform >
    <link name="${prefix}base" />
    <joint name="${prefix}base_link-base" type="fixed">
      <origin xyz="0 0 0" rpy="0 0 0"/>
      <parent link="${prefix}base_link"/>
      <child link="${prefix}base"/>
    </joint-->
  <joint name="bridge2_joint_EA_X" type="prismatic">
    <parent link="x_rail"/>
    <child link="bridge2"/>
    <origin rpy="0 0 0" xyz="0 0 0"/>
    <axis xyz="1 0 0"/>
    <limit effort="100000" lower="2.599" upper="39.805" velocity="2.618"/>
    <dynamics damping="0.2" friction="0"/>
  </joint>
  <link name="bridge2">
    <inertial>
      <origin xyz="0.0 0.0 0.0"/>
      <mass value="120.00000"/>
      <inertia ixx="-4.98000" ixy="-0.00000" ixz="2.70000" iyy="-5.95200" iyz="-0.00000" izz="0.82800"/>
    </inertial>
    <visual>
      <origin rpy="0 0 3.14159265359" xyz="0.0 12.2364997 0.0"/>
      <geometry>
        <mesh filename="package://rfl_description/meshes/visual/y_gantry.stl"/>
      </geometry>
      <material name="">
        <color rgba="0.9254902 0.9254902 0.9058824 1"/>
      </material>
    </visual>
    <collision>
      <origin rpy="0 0 3.14159265359" xyz="0.0 12.2364997 0.0"/>
      <geometry>
        <mesh filename="package://rfl_description/meshes/collision/y_gantry.stl"/>
      </geometry>
    </collision>
  </link>
  <joint name="robot21_joint_EA_Y" type="prismatic">
    <parent link="bridge2"/>
    <child link="robot21_xy_cart"/>
    <origin rpy="0 0 0 " xyz="0 0 0"/>
    <axis xyz="0 -1 0"/>
    <limit effort="100000" lower="-9.65" upper="0.0" velocity="2.618"/>
    <dynamics damping="0.2" friction="0"/>
  </joint>
  <link name="robot21_xy_cart">
    <inertial>
      <origin xyz="0.0 0.0 0.0"/>
      <mass value="120.00000"/>
      <inertia ixx="-4.98000" ixy="-0.00000" ixz="2.70000" iyy="-5.95200" iyz="-0.00000" izz="0.82800"/>
    </inertial>
    <visual>
      <origin rpy="0 0 3.14159265359" xyz="0.0 0.0 0.0"/>
      <geometry>
        <mesh filename="package://rfl_description/meshes/visual/group2_xy_cart.stl"/>
      </geometry>
      <material name="">
        <color rgba="0.9254902 0.9254902 0.9058824 1"/>
      </material>
    </visual>
    <collision>
      <origin rpy="0 0 3.14159265359" xyz="0.0 0.0 0.0"/>
      <geometry>
        <mesh filename="package://rfl_description/meshes/collision/group2_xy_cart.stl"/>
      </geometry>
    </collision>
  </link>
  <joint name="robot21_joint_EA_Z" type="prismatic">
    <parent link="robot21_xy_cart"/>
    <child link="robot21_base"/>
    <origin rpy="0 0 0 " xyz="0 0 0"/>
    <axis xyz="0 0 -1"/>
    <limit effort="100000" lower="-4.915" upper="-1.005" velocity="2.618"/>
    <dynamics damping="0.2" friction="0"/>
  </joint>
  <link name="robot21_base">
    <inertial>
      <origin xyz="0.0 0.0 0.0"/>
      <mass value="120.00000"/>
      <inertia ixx="-4.98000" ixy="-0.00000" ixz="2.70000" iyy="-5.95200" iyz="-0.00000" izz="0.82800"/>
    </inertial>
    <visual>
      <origin rpy="0 0 3.14159265359" xyz="0.0 0.0 0.0"/>
      <geometry>
        <mesh filename="package://rfl_description/meshes/visual/group2_z_axis.stl"/>
      </geometry>
      <material name="">
        <color rgba="0.9254902 0.9254902 0.9058824 1"/>
      </material>
    </visual>
    <collision>
      <origin rpy="0 0 3.14159265359" xyz="0.0 0.0 0.0"/>
      <geometry>
        <mesh filename="package://rfl_description/meshes/collision/group2_z_axis.stl"/>
      </geometry>
    </collision>
  </link>
  <joint name="robot21_joint_0" type="fixed">
    <parent link="robot21_base"/>
    <child link="robot21_base_link"/>
    <origin rpy="3.14159265359 0 3.14159265359" xyz="0 0 0"/>
    <dynamics damping="0.2" friction="0"/>
  </joint>
  <!-- link list -->
  <link name="robot21_base_link">
    <inertial>
      <origin xyz="0.0 0.0 0.0"/>
      <mass value="120.00000"/>
      <inertia ixx="-4.98000" ixy="0.00000" ixz="2.70000" iyy="-5.95200" iyz="0.00000" izz="0.82800"/>
    </inertial>
    <visual>
      <geometry>
        <mesh filename="package://abb_irb4600_40_255/meshes/visual/base_link.stl"/>
      </geometry>
      <material name="">
        <color rgba="0.7725490 0.7803922 0.7686275 1"/>
      </material>
    </visual>
    <collision>
      <geometry>
        <mesh filename="package://abb_irb4600_40_255/meshes/collision/base_link.stl"/>
      </geometry>
    </collision>
  </link>
  <link name="robot21_link_1">
    <inertial>
      <origin xyz="0.18000 0.00000 0.50000"/>
      <mass value="120.00000"/>
      <inertia ixx="-4.98000" ixy="0.00000" ixz="2.70000" iyy="-5.95200" iyz="0.00000" izz="0.82800"/>
    </inertial>
    <visual>
      <geometry>
        <mesh filename="package://abb_irb4600_40_255/meshes/visual/link_1.stl"/>
      </geometry>
      <material name="">
        <color rgba="0.7725490 0.7803922 0.7686275 1"/>
      </material>
    </visual>
    <collision>
      <geometry>
        <mesh filename="package://abb_irb4600_40_255/meshes/collision/link_1.stl"/>
      </geometry>
    </collision>
  </link>
  <link name="robot21_link_2">
    <inertial>
      <origin xyz="0.94000 0.08000 -0.34000"/>
      <mass value="120.00000"/>
      <inertia ixx="-2.96000" ixy="2.25600" ixz="-9.58800" iyy="-18.72601" iyz="-0.81600" izz="-14.95000"/>
    </inertial>
    <visual>
      <geometry>
        <mesh filename="package://abb_irb4600_40_255/meshes/visual/link_2.stl"/>
      </geometry>
      <material name="">
        <color rgba="0.7725490 0.7803922 0.7686275 1"/>
      </material>
    </visual>
    <collision>
      <geometry>
        <mesh filename="package://abb_irb4600_40_255/meshes/collision/link_2.stl"/>
      </geometry>
    </collision>
  </link>
  <link name="robot21_link_3">
    <inertial>
      <origin xyz="0.07000 -0.26600 0.08800"/>
      <mass value="120.00000"/>
      <inertia ixx="1.34500" ixy="0.55860" ixz="0.18480" iyy="4.65068" iyz="-0.70224" izz="2.76032"/>
    </inertial>
    <visual>
      <geometry>
        <mesh filename="package://abb_irb4600_40_255/meshes/visual/link_3.stl"/>
      </geometry>
      <material name="">
        <color rgba="0.7725490 0.7803922 0.7686275 1"/>
      </material>
    </visual>
    <collision>
      <geometry>
        <mesh filename="package://abb_irb4600_40_255/meshes/collision/link_3.stl"/>
      </geometry>
    </collision>
  </link>
  <link name="robot21_link_4">
    <inertial>
      <origin xyz="0.00000 0.00000 1.00000"/>
      <mass value="40.00000"/>
      <inertia ixx="-8.00000" ixy="0.00000" ixz="0.00000" iyy="-8.00000" iyz="0.00000" izz="0.48200"/>
    </inertial>
    <visual>
      <geometry>
        <mesh filename="package://abb_irb4600_40_255/meshes/visual/link_4.stl"/>
      </geometry>
      <material name="">
        <color rgba="0.7725490 0.7803922 0.7686275 1"/>
      </material>
    </visual>
    <collision>
      <geometry>
        <mesh filename="package://abb_irb4600_40_255/meshes/collision/link_4.stl"/>
      </geometry>
    </collision>
  </link>
  <link name="robot21_link_5">
    <inertial>
      <origin xyz="0.14000 0.00000 0.00000"/>
      <mass value="10.00000"/>
      <inertia ixx="0.04000" ixy="0.00000" ixz="0.00000" iyy="-0.00900" iyz="0.00000" izz="-0.00400"/>
    </inertial>
    <visual>
      <geometry>
        <mesh filename="package://abb_irb4600_40_255/meshes/visual/link_5.stl"/>
      </geometry>
      <material name="">
        <color rgba="0.7725490 0.7803922 0.7686275 1"/>
      </material>
    </visual>
    <collision>
      <geometry>
        <mesh filename="package://abb_irb4600_40_255/meshes/collision/link_5.stl"/>
      </geometry>
    </collision>
  </link>
  <link name="robot21_link_6">
    <inertial>
      <origin xyz="0.08100 -0.09100 0.33200"/>
      <mass value="5.00000"/>
      <inertia ixx="-0.29652" ixy="-0.03686" ixz="0.09396" iyy="-0.28792" iyz="-0.10556" izz="-0.04621"/>
    </inertial>
    <visual>
      <geometry>
        <mesh filename="package://abb_irb4600_40_255/meshes/visual/link_6.stl"/>
      </geometry>
      <material name="">
        <color rgba="0.1882353 0.1960784 0.2039216 1"/>
      </material>
    </visual>
    <collision>
      <geometry>
        <mesh filename="package://abb_irb4600_40_255/meshes/collision/link_6.stl"/>
      </geometry>
    </collision>
  </link>
  <link name="robot21_tool0"/>
  <!-- end of link list -->
  <!-- joint list -->
  <joint name="robot21_joint_1" type="revolute">
    <parent link="robot21_base_link"/>
    <child link="robot21_link_1"/>
    <origin rpy="0 0 0 " xyz="0 0 0"/>
    <axis xyz="0 0 1"/>
    <!-- (-180 to 180) -->
    <limit effort="100000" lower="-3.14159265359" upper="3.14159265359" velocity="2.618"/>
    <dynamics damping="0.2" friction="0"/>
  </joint>
  <joint name="robot21_joint_2" type="revolute">
    <parent link="robot21_link_1"/>
    <child link="robot21_link_2"/>
    <origin rpy="0 0 0 " xyz="0.175 0 0.495"/>
    <axis xyz="0 1 0"/>
    <!-- (-90 to 150) -->
    <limit effort="100000" lower="-1.57079632679" upper="2.61799387799" velocity="2.618"/>
    <dynamics damping="0.2" friction="0"/>
  </joint>
  <joint name="robot21_joint_3" type="revolute">
    <parent link="robot21_link_2"/>
    <child link="robot21_link_3"/>
    <origin rpy="0 0 0 " xyz="0 0 1.095"/>
    <axis xyz="0 1 0"/>
    <!-- (-180 to 75) -->
    <limit effort="100000" lower="-3.14159265359" upper="1.308996939" velocity="2.618"/>
    <dynamics damping="0.2" friction="0"/>
  </joint>
  <joint name="robot21_joint_4" type="revolute">
    <parent link="robot21_link_3"/>
    <child link="robot21_link_4"/>
    <origin rpy="0 0 0 " xyz="0.331 0 0.175"/>
    <axis xyz="1 0 0"/>
    <!-- (-400 to 400) -->
    <limit effort="10000" lower="-6.98131700798" upper="6.98131700798" velocity="6.2832"/>
    <dynamics damping="0.2" friction="0"/>
  </joint>
  <joint name="robot21_joint_5" type="revolute">
    <parent link="robot21_link_4"/>
    <child link="robot21_link_5"/>
    <origin rpy="0 0 0 " xyz="0.939 0 0"/>
    <axis xyz="0 1 0"/>
    <!-- (-125 to 120) -->
    <limit effort="100000" lower="-2.18166" upper="2.18166156499" velocity="6.2832"/>
    <dynamics damping="0.2" friction="0"/>
  </joint>
  <joint name="robot21_joint_6" type="revolute">
    <parent link="robot21_link_5"/>
    <child link="robot21_link_6"/>
    <origin rpy="0 1.57079632679 0" xyz="0.135 0 0"/>
    <axis xyz="0 0 1"/>
    <!-- (-400 to 400) -->
    <limit effort="100000" lower="-6.98131700798" upper="6.98131700798" velocity="7.854"/>
    <dynamics damping="0.2" friction="0"/>
  </joint>
  <joint name="robot21_joint_6-tool0" type="fixed">
    <parent link="robot21_link_6"/>
    <child link="robot21_tool0"/>
    <origin rpy="0 0 0" xyz="0 0 0"/>
  </joint>
  <!-- end of joint list -->
  <!-- ROS base_link to ABB World Coordinates transform >
    <link name="${prefix}base" />
    <joint name="${prefix}base_link-base" type="fixed">
      <origin xyz="0 0 0" rpy="0 0 0"/>
      <parent link="${prefix}base_link"/>
      <child link="${prefix}base"/>
    </joint-->
  <joint name="robot22_joint_EA_Y" type="prismatic">
    <parent link="bridge2"/>
    <child link="robot22_xy_cart"/>
    <origin rpy="0 0 0 " xyz="0 0 0"/>
    <axis xyz="0 -1 0"/>
    <limit effort="100000" lower="-12.237" upper="-2.587" velocity="2.618"/>
    <dynamics damping="0.2" friction="0"/>
  </joint>
  <link name="robot22_xy_cart">
    <inertial>
      <origin xyz="0.0 0.0 0.0"/>
      <mass value="120.00000"/>
      <inertia ixx="-4.98000" ixy="-0.00000" ixz="2.70000" iyy="-5.95200" iyz="-0.00000" izz="0.82800"/>
    </inertial>
    <visual>
      <origin rpy="0 0 3.14159265359" xyz="0.0 0.0 0.0"/>
      <geometry>
        <mesh filename="package://rfl_description/meshes/visual/group1_xy_cart.stl"/>
      </geometry>
      <material name="">
        <color rgba="0.9254902 0.9254902 0.9058824 1"/>
      </material>
    </visual>
    <collision>
      <origin rpy="0 0 3.14159265359" xyz="0.0 0.0 0.0"/>
      <geometry>
        <mesh filename="package://rfl_description/meshes/collision/group1_xy_cart.stl"/>
      </geometry>
    </collision>
  </link>
  <joint name="robot22_joint_EA_Z" type="prismatic">
    <parent link="robot22_xy_cart"/>
    <child link="robot22_base"/>
    <origin rpy="0 0 0 " xyz="0 0 0"/>
    <axis xyz="0 0 -1"/>
    <limit effort="100000" lower="-4.915" upper="-1.005" velocity="2.618"/>
    <dynamics damping="0.2" friction="0"/>
  </joint>
  <link name="robot22_base">
    <inertial>
      <origin xyz="0.0 0.0 0.0"/>
      <mass value="120.00000"/>
      <inertia ixx="-4.98000" ixy="-0.00000" ixz="2.70000" iyy="-5.95200" iyz="-0.00000" izz="0.82800"/>
    </inertial>
    <visual>
      <origin rpy="0 0 3.14159265359" xyz="0.0 0.0 0.0"/>
      <geometry>
        <mesh filename="package://rfl_description/meshes/visual/group1_z_axis.stl"/>
      </geometry>
      <material name="">
        <color rgba="0.9254902 0.9254902 0.9058824 1"/>
      </material>
    </visual>
    <collision>
      <origin rpy="0 0 3.14159265359" xyz="0.0 0.0 0.0"/>
      <geometry>
        <mesh filename="package://rfl_description/meshes/collision/group1_z_axis.stl"/>
      </geometry>
    </collision>
  </link>
  <joint name="robot22_joint_0" type="fixed">
    <parent link="robot22_base"/>
    <child link="robot22_base_link"/>
    <origin rpy="3.14159265359 0 3.14159265359" xyz="0 0 0"/>
    <dynamics damping="0.2" friction="0"/>
  </joint>
  <!-- link list -->
  <link name="robot22_base_link">
    <inertial>
      <origin xyz="0.0 0.0 0.0"/>
      <mass value="120.00000"/>
      <inertia ixx="-4.98000" ixy="0.00000" ixz="2.70000" iyy="-5.95200" iyz="0.00000" izz="0.82800"/>
    </inertial>
    <visual>
      <geometry>
        <mesh filename="package://abb_irb4600_40_255/meshes/visual/base_link.stl"/>
      </geometry>
      <material name="">
        <color rgba="0.7725490 0.7803922 0.7686275 1"/>
      </material>
    </visual>
    <collision>
      <geometry>
        <mesh filename="package://abb_irb4600_40_255/meshes/collision/base_link.stl"/>
      </geometry>
    </collision>
  </link>
  <link name="robot22_link_1">
    <inertial>
      <origin xyz="0.18000 0.00000 0.50000"/>
      <mass value="120.00000"/>
      <inertia ixx="-4.98000" ixy="0.00000" ixz="2.70000" iyy="-5.95200" iyz="0.00000" izz="0.82800"/>
    </inertial>
    <visual>
      <geometry>
        <mesh filename="package://abb_irb4600_40_255/meshes/visual/link_1.stl"/>
      </geometry>
      <material name="">
        <color rgba="0.7725490 0.7803922 0.7686275 1"/>
      </material>
    </visual>
    <collision>
      <geometry>
        <mesh filename="package://abb_irb4600_40_255/meshes/collision/link_1.stl"/>
      </geometry>
    </collision>
  </link>
  <link name="robot22_link_2">
    <inertial>
      <origin xyz="0.94000 0.08000 -0.34000"/>
      <mass value="120.00000"/>
      <inertia ixx="-2.96000" ixy="2.25600" ixz="-9.58800" iyy="-18.72601" iyz="-0.81600" izz="-14.95000"/>
    </inertial>
    <visual>
      <geometry>
        <mesh filename="package://abb_irb4600_40_255/meshes/visual/link_2.stl"/>
      </geometry>
      <material name="">
        <color rgba="0.7725490 0.7803922 0.7686275 1"/>
      </material>
    </visual>
    <collision>
      <geometry>
        <mesh filename="package://abb_irb4600_40_255/meshes/collision/link_2.stl"/>
      </geometry>
    </collision>
  </link>
  <link name="robot22_link_3">
    <inertial>
      <origin xyz="0.07000 -0.26600 0.08800"/>
      <mass value="120.00000"/>
      <inertia ixx="1.34500" ixy="0.55860" ixz="0.18480" iyy="4.65068" iyz="-0.70224" izz="2.76032"/>
    </inertial>
    <visual>
      <geometry>
        <mesh filename="package://abb_irb4600_40_255/meshes/visual/link_3.stl"/>
      </geometry>
      <material name="">
        <color rgba="0.7725490 0.7803922 0.7686275 1"/>
      </material>
    </visual>
    <collision>
      <geometry>
        <mesh filename="package://abb_irb4600_40_255/meshes/collision/link_3.stl"/>
      </geometry>
    </collision>
  </link>
  <link name="robot22_link_4">
    <inertial>
      <origin xyz="0.00000 0.00000 1.00000"/>
      <mass value="40.00000"/>
      <inertia ixx="-8.00000" ixy="0.00000" ixz="0.00000" iyy="-8.00000" iyz="0.00000" izz="0.48200"/>
    </inertial>
    <visual>
      <geometry>
        <mesh filename="package://abb_irb4600_40_255/meshes/visual/link_4.stl"/>
      </geometry>
      <material name="">
        <color rgba="0.7725490 0.7803922 0.7686275 1"/>
      </material>
    </visual>
    <collision>
      <geometry>
        <mesh filename="package://abb_irb4600_40_255/meshes/collision/link_4.stl"/>
      </geometry>
    </collision>
  </link>
  <link name="robot22_link_5">
    <inertial>
      <origin xyz="0.14000 0.00000 0.00000"/>
      <mass value="10.00000"/>
      <inertia ixx="0.04000" ixy="0.00000" ixz="0.00000" iyy="-0.00900" iyz="0.00000" izz="-0.00400"/>
    </inertial>
    <visual>
      <geometry>
        <mesh filename="package://abb_irb4600_40_255/meshes/visual/link_5.stl"/>
      </geometry>
      <material name="">
        <color rgba="0.7725490 0.7803922 0.7686275 1"/>
      </material>
    </visual>
    <collision>
      <geometry>
        <mesh filename="package://abb_irb4600_40_255/meshes/collision/link_5.stl"/>
      </geometry>
    </collision>
  </link>
  <link name="robot22_link_6">
    <inertial>
      <origin xyz="0.08100 -0.09100 0.33200"/>
      <mass value="5.00000"/>
      <inertia ixx="-0.29652" ixy="-0.03686" ixz="0.09396" iyy="-0.28792" iyz="-0.10556" izz="-0.04621"/>
    </inertial>
    <visual>
      <geometry>
        <mesh filename="package://abb_irb4600_40_255/meshes/visual/link_6.stl"/>
      </geometry>
      <material name="">
        <color rgba="0.1882353 0.1960784 0.2039216 1"/>
      </material>
    </visual>
    <collision>
      <geometry>
        <mesh filename="package://abb_irb4600_40_255/meshes/collision/link_6.stl"/>
      </geometry>
    </collision>
  </link>
  <link name="robot22_tool0"/>
  <!-- end of link list -->
  <!-- joint list -->
  <joint name="robot22_joint_1" type="revolute">
    <parent link="robot22_base_link"/>
    <child link="robot22_link_1"/>
    <origin rpy="0 0 0 " xyz="0 0 0"/>
    <axis xyz="0 0 1"/>
    <!-- (-180 to 180) -->
    <limit effort="100000" lower="-3.14159265359" upper="3.14159265359" velocity="2.618"/>
    <dynamics damping="0.2" friction="0"/>
  </joint>
  <joint name="robot22_joint_2" type="revolute">
    <parent link="robot22_link_1"/>
    <child link="robot22_link_2"/>
    <origin rpy="0 0 0 " xyz="0.175 0 0.495"/>
    <axis xyz="0 1 0"/>
    <!-- (-90 to 150) -->
    <limit effort="100000" lower="-1.57079632679" upper="2.61799387799" velocity="2.618"/>
    <dynamics damping="0.2" friction="0"/>
  </joint>
  <joint name="robot22_joint_3" type="revolute">
    <parent link="robot22_link_2"/>
    <child link="robot22_link_3"/>
    <origin rpy="0 0 0 " xyz="0 0 1.095"/>
    <axis xyz="0 1 0"/>
    <!-- (-180 to 75) -->
    <limit effort="100000" lower="-3.14159265359" upper="1.308996939" velocity="2.618"/>
    <dynamics damping="0.2" friction="0"/>
  </joint>
  <joint name="robot22_joint_4" type="revolute">
    <parent link="robot22_link_3"/>
    <child link="robot22_link_4"/>
    <origin rpy="0 0 0 " xyz="0.331 0 0.175"/>
    <axis xyz="1 0 0"/>
    <!-- (-400 to 400) -->
    <limit effort="10000" lower="-6.98131700798" upper="6.98131700798" velocity="6.2832"/>
    <dynamics damping="0.2" friction="0"/>
  </joint>
  <joint name="robot22_joint_5" type="revolute">
    <parent link="robot22_link_4"/>
    <child link="robot22_link_5"/>
    <origin rpy="0 0 0 " xyz="0.939 0 0"/>
    <axis xyz="0 1 0"/>
    <!-- (-125 to 120) -->
    <limit effort="100000" lower="-2.18166" upper="2.18166156499" velocity="6.2832"/>
    <dynamics damping="0.2" friction="0"/>
  </joint>
  <joint name="robot22_joint_6" type="revolute">
    <parent link="robot22_link_5"/>
    <child link="robot22_link_6"/>
    <origin rpy="0 1.57079632679 0" xyz="0.135 0 0"/>
    <axis xyz="0 0 1"/>
    <!-- (-400 to 400) -->
    <limit effort="100000" lower="-6.98131700798" upper="6.98131700798" velocity="7.854"/>
    <dynamics damping="0.2" friction="0"/>
  </joint>
  <joint name="robot22_joint_6-tool0" type="fixed">
    <parent link="robot22_link_6"/>
    <child link="robot22_tool0"/>
    <origin rpy="0 0 0" xyz="0 0 0"/>
  </joint>
  <!-- end of joint list -->
  <!-- ROS base_link to ABB World Coordinates transform >
    <link name="${prefix}base" />
    <joint name="${prefix}base_link-base" type="fixed">
      <origin xyz="0 0 0" rpy="0 0 0"/>
      <parent link="${prefix}base_link"/>
      <child link="${prefix}base"/>
    </joint-->
</robot>
