<?xml version="1.0" encoding="utf-8"?>
<robot name="panda">
  <link name="panda_link0">
    <visual>
      <geometry>
        <mesh filename="package://franka_description/meshes/visual/link0.dae.obj"/>
      </geometry>
    </visual>
    <collision>
      <geometry>
        <mesh filename="package://franka_description/meshes/collision/link0.stl"/>
      </geometry>
    </collision>
  </link>
  <link name="panda_link0_sc">
    <collision>
      <origin xyz="-0.075 0.0 0.06" rpy="0.0 1.5707963267948966 0.0"/>
      <geometry>
        <cylinder radius="0.09" length="0.03"/>
      </geometry>
    </collision>
    <collision>
      <origin xyz="-0.06 0.0 0.06" rpy="0.0 0.0 0.0"/>
      <geometry>
        <sphere radius="0.09"/>
      </geometry>
    </collision>
    <collision>
      <origin xyz="-0.09 0.0 0.06" rpy="0.0 0.0 0.0"/>
      <geometry>
        <sphere radius="0.09"/>
      </geometry>
    </collision>
  </link>
  <link name="panda_link1">
    <visual>
      <geometry>
        <mesh filename="package://franka_description/meshes/visual/link1.dae.obj"/>
      </geometry>
    </visual>
    <collision>
      <geometry>
        <mesh filename="package://franka_description/meshes/collision/link1.stl"/>
      </geometry>
    </collision>
  </link>
  <link name="panda_link1_sc">
    <collision>
      <origin xyz="0.0 0.0 -0.1915" rpy="0.0 0.0 0.0"/>
      <geometry>
        <cylinder radius="0.09" length="0.283"/>
      </geometry>
    </collision>
    <collision>
      <origin xyz="0.0 0.0 -0.05000000000000002" rpy="0.0 0.0 0.0"/>
      <geometry>
        <sphere radius="0.09"/>
      </geometry>
    </collision>
    <collision>
      <origin xyz="0.0 0.0 -0.33299999999999996" rpy="0.0 0.0 0.0"/>
      <geometry>
        <sphere radius="0.09"/>
      </geometry>
    </collision>
  </link>
  <link name="panda_link2">
    <visual>
      <geometry>
        <mesh filename="package://franka_description/meshes/visual/link2.dae.obj"/>
      </geometry>
    </visual>
    <collision>
      <geometry>
        <mesh filename="package://franka_description/meshes/collision/link2.stl"/>
      </geometry>
    </collision>
  </link>
  <link name="panda_link2_sc">
    <collision>
      <origin xyz="0.0 0.0 0.0" rpy="0.0 0.0 0.0"/>
      <geometry>
        <cylinder radius="0.09" length="0.12"/>
      </geometry>
    </collision>
    <collision>
      <origin xyz="0.0 0.0 0.06" rpy="0.0 0.0 0.0"/>
      <geometry>
        <sphere radius="0.09"/>
      </geometry>
    </collision>
    <collision>
      <origin xyz="0.0 0.0 -0.06" rpy="0.0 0.0 0.0"/>
      <geometry>
        <sphere radius="0.09"/>
      </geometry>
    </collision>
  </link>
  <link name="panda_link3">
    <visual>
      <geometry>
        <mesh filename="package://franka_description/meshes/visual/link3.dae.obj"/>
      </geometry>
    </visual>
    <collision>
      <geometry>
        <mesh filename="package://franka_description/meshes/collision/link3.stl"/>
      </geometry>
    </collision>
  </link>
  <link name="panda_link3_sc">
    <collision>
      <origin xyz="0.0 0.0 -0.145" rpy="0.0 0.0 0.0"/>
      <geometry>
        <cylinder radius="0.09" length="0.15"/>
      </geometry>
    </collision>
    <collision>
      <origin xyz="0.0 0.0 -0.06999999999999999" rpy="0.0 0.0 0.0"/>
      <geometry>
        <sphere radius="0.09"/>
      </geometry>
    </collision>
    <collision>
      <origin xyz="0.0 0.0 -0.21999999999999997" rpy="0.0 0.0 0.0"/>
      <geometry>
        <sphere radius="0.09"/>
      </geometry>
    </collision>
  </link>
  <link name="panda_link4">
    <visual>
      <geometry>
        <mesh filename="package://franka_description/meshes/visual/link4.dae.obj"/>
      </geometry>
    </visual>
    <collision>
      <geometry>
        <mesh filename="package://franka_description/meshes/collision/link4.stl"/>
      </geometry>
    </collision>
  </link>
  <link name="panda_link4_sc">
    <collision>
      <origin xyz="0.0 0.0 0.0" rpy="0.0 0.0 0.0"/>
      <geometry>
        <cylinder radius="0.09" length="0.12"/>
      </geometry>
    </collision>
    <collision>
      <origin xyz="0.0 0.0 0.06" rpy="0.0 0.0 0.0"/>
      <geometry>
        <sphere radius="0.09"/>
      </geometry>
    </collision>
    <collision>
      <origin xyz="0.0 0.0 -0.06" rpy="0.0 0.0 0.0"/>
      <geometry>
        <sphere radius="0.09"/>
      </geometry>
    </collision>
  </link>
  <link name="panda_link5">
    <visual>
      <geometry>
        <mesh filename="package://franka_description/meshes/visual/link5.dae.obj"/>
      </geometry>
    </visual>
    <collision>
      <geometry>
        <mesh filename="package://franka_description/meshes/collision/link5.stl"/>
      </geometry>
    </collision>
  </link>
  <link name="panda_link5_sc">
    <collision>
      <origin xyz="0.0 0.0 -0.26" rpy="0.0 0.0 0.0"/>
      <geometry>
        <cylinder radius="0.09" length="0.1"/>
      </geometry>
    </collision>
    <collision>
      <origin xyz="0.0 0.0 -0.21000000000000002" rpy="0.0 0.0 0.0"/>
      <geometry>
        <sphere radius="0.09"/>
      </geometry>
    </collision>
    <collision>
      <origin xyz="0.0 0.0 -0.31" rpy="0.0 0.0 0.0"/>
      <geometry>
        <sphere radius="0.09"/>
      </geometry>
    </collision>
    <collision>
      <origin xyz="0.0 0.08 -0.13" rpy="0.0 0.0 0.08"/>
      <geometry>
        <cylinder radius="0.055" length="0.14"/>
      </geometry>
    </collision>
    <collision>
      <origin xyz="0.0 0.08 -0.06" rpy="0.0 0.0 0.0"/>
      <geometry>
        <sphere radius="0.055"/>
      </geometry>
    </collision>
    <collision>
      <origin xyz="0.0 0.08 -0.2" rpy="0.0 0.0 0.0"/>
      <geometry>
        <sphere radius="0.055"/>
      </geometry>
    </collision>
  </link>
  <link name="panda_link6">
    <visual>
      <geometry>
        <mesh filename="package://franka_description/meshes/visual/link6.dae.obj"/>
      </geometry>
    </visual>
    <collision>
      <geometry>
        <mesh filename="package://franka_description/meshes/collision/link6.stl"/>
      </geometry>
    </collision>
  </link>
  <link name="panda_link6_sc">
    <collision>
      <origin xyz="0.0 0.0 -0.03" rpy="0.0 0.0 0.0"/>
      <geometry>
        <cylinder radius="0.08" length="0.08"/>
      </geometry>
    </collision>
    <collision>
      <origin xyz="0.0 0.0 0.010000000000000002" rpy="0.0 0.0 0.0"/>
      <geometry>
        <sphere radius="0.08"/>
      </geometry>
    </collision>
    <collision>
      <origin xyz="0.0 0.0 -0.07" rpy="0.0 0.0 0.0"/>
      <geometry>
        <sphere radius="0.08"/>
      </geometry>
    </collision>
  </link>
  <link name="panda_link7">
    <visual>
      <geometry>
        <mesh filename="package://franka_description/meshes/visual/link7.dae.obj"/>
      </geometry>
    </visual>
    <collision>
      <geometry>
        <mesh filename="package://franka_description/meshes/collision/link7.stl"/>
      </geometry>
    </collision>
  </link>
  <link name="panda_link7_sc">
    <collision>
      <origin xyz="0.0 0.0 0.01" rpy="0.0 0.0 0.0"/>
      <geometry>
        <cylinder radius="0.07" length="0.14"/>
      </geometry>
    </collision>
    <collision>
      <origin xyz="0.0 0.0 0.08" rpy="0.0 0.0 0.0"/>
      <geometry>
        <sphere radius="0.07"/>
      </geometry>
    </collision>
    <collision>
      <origin xyz="0.0 0.0 -0.060000000000000005" rpy="0.0 0.0 0.0"/>
      <geometry>
        <sphere radius="0.07"/>
      </geometry>
    </collision>
    <collision>
      <origin xyz="0.06 0.0 0.082" rpy="0.0 1.5707963267948966 0.0"/>
      <geometry>
        <cylinder radius="0.06" length="0.01"/>
      </geometry>
    </collision>
    <collision>
      <origin xyz="0.065 0.0 0.082" rpy="0.0 0.0 0.0"/>
      <geometry>
        <sphere radius="0.06"/>
      </geometry>
    </collision>
    <collision>
      <origin xyz="0.055 0.0 0.082" rpy="0.0 0.0 0.0"/>
      <geometry>
        <sphere radius="0.06"/>
      </geometry>
    </collision>
  </link>
  <link name="panda_link8"/>
  <link name="panda_hand">
    <visual>
      <geometry>
        <mesh filename="package://franka_description/meshes/visual/hand.dae.obj"/>
      </geometry>
    </visual>
    <collision>
      <geometry>
        <mesh filename="package://franka_description/meshes/collision/hand.stl"/>
      </geometry>
    </collision>
  </link>
  <link name="panda_hand_sc">
    <collision>
      <origin xyz="0.0 0.0 0.04" rpy="1.5707963267948966 0.0 0.0"/>
      <geometry>
        <cylinder radius="0.07" length="0.1"/>
      </geometry>
    </collision>
    <collision>
      <origin xyz="0.0 0.05 0.04" rpy="0.0 0.0 0.0"/>
      <geometry>
        <sphere radius="0.07"/>
      </geometry>
    </collision>
    <collision>
      <origin xyz="0.0 -0.05 0.04" rpy="0.0 0.0 0.0"/>
      <geometry>
        <sphere radius="0.07"/>
      </geometry>
    </collision>
    <collision>
      <origin xyz="0.0 0.0 0.1" rpy="1.5707963267948966 0.0 0.0"/>
      <geometry>
        <cylinder radius="0.05" length="0.1"/>
      </geometry>
    </collision>
    <collision>
      <origin xyz="0.0 0.05 0.1" rpy="0.0 0.0 0.0"/>
      <geometry>
        <sphere radius="0.05"/>
      </geometry>
    </collision>
    <collision>
      <origin xyz="0.0 -0.05 0.1" rpy="0.0 0.0 0.0"/>
      <geometry>
        <sphere radius="0.05"/>
      </geometry>
    </collision>
  </link>
  <link name="panda_hand_tcp"/>
  <link name="panda_leftfinger">
    <visual>
      <geometry>
        <mesh filename="package://franka_description/meshes/visual/finger.dae.obj"/>
      </geometry>
    </visual>
    <collision>
      <origin xyz="0.0 0.0185 0.011" rpy="0.0 0.0 0.0"/>
      <geometry>
        <box size="0.022 0.015 0.02"/>
      </geometry>
    </collision>
    <collision>
      <origin xyz="0.0 0.0068 0.0022" rpy="0.0 0.0 0.0"/>
      <geometry>
        <box size="0.022 0.0088 0.0038"/>
      </geometry>
    </collision>
    <collision>
      <origin xyz="0.0 0.0159 0.02835" rpy="0.5235987755982988 0.0 0.0"/>
      <geometry>
        <box size="0.0175 0.007 0.0235"/>
      </geometry>
    </collision>
    <collision>
      <origin xyz="0.0 0.00758 0.04525" rpy="0.0 0.0 0.0"/>
      <geometry>
        <box size="0.0175 0.0152 0.0185"/>
      </geometry>
    </collision>
  </link>
  <link name="panda_rightfinger">
    <visual>
      <origin xyz="0.0 0.0 0.0" rpy="0.0 0.0 3.141592653589793"/>
      <geometry>
        <mesh filename="package://franka_description/meshes/visual/finger.dae.obj"/>
      </geometry>
    </visual>
    <collision>
      <origin xyz="0.0 -0.0185 0.011" rpy="0.0 0.0 0.0"/>
      <geometry>
        <box size="0.022 0.015 0.02"/>
      </geometry>
    </collision>
    <collision>
      <origin xyz="0.0 -0.0068 0.0022" rpy="0.0 0.0 0.0"/>
      <geometry>
        <box size="0.022 0.0088 0.0038"/>
      </geometry>
    </collision>
    <collision>
      <origin xyz="0.0 -0.0159 0.02835" rpy="-0.5235987755982988 0.0 0.0"/>
      <geometry>
        <box size="0.0175 0.007 0.0235"/>
      </geometry>
    </collision>
    <collision>
      <origin xyz="0.0 -0.00758 0.04525" rpy="0.0 0.0 0.0"/>
      <geometry>
        <box size="0.0175 0.0152 0.0185"/>
      </geometry>
    </collision>
  </link>
  <joint name="panda_link0_sc_joint" type="fixed">
    <parent link="panda_link0"/>
    <child link="panda_link0_sc"/>
    <axis xyz="1.0 0.0 0.0"/>
    <origin xyz="0.0 0.0 0.0" rpy="0.0 0.0 0.0"/>
  </joint>
  <joint name="panda_link1_sc_joint" type="fixed">
    <parent link="panda_link1"/>
    <child link="panda_link1_sc"/>
    <axis xyz="1.0 0.0 0.0"/>
    <origin xyz="0.0 0.0 0.0" rpy="0.0 0.0 0.0"/>
  </joint>
  <joint name="panda_joint1" type="revolute">
    <parent link="panda_link0"/>
    <child link="panda_link1"/>
    <axis xyz="0.0 0.0 1.0"/>
    <dynamics damping="0.003" friction="0.0" D="1" K="7000" mu_coulomb="0" mu_viscous="16"/>
    <limit lower="-2.8973" upper="2.8973" effort="87.0" velocity="2.175"/>
    <safety_controller k_position="100.0" soft_lower_limit="-2.8973" soft_upper_limit="2.8973" k_velocity="40.0"/>
    <origin xyz="0.0 0.0 0.333" rpy="0.0 0.0 0.0"/>
  </joint>
  <joint name="panda_link2_sc_joint" type="fixed">
    <parent link="panda_link2"/>
    <child link="panda_link2_sc"/>
    <axis xyz="1.0 0.0 0.0"/>
    <origin xyz="0.0 0.0 0.0" rpy="0.0 0.0 0.0"/>
  </joint>
  <joint name="panda_joint2" type="revolute">
    <parent link="panda_link1"/>
    <child link="panda_link2"/>
    <axis xyz="0.0 0.0 1.0"/>
    <dynamics damping="0.003" friction="0.0" D="1" K="7000" mu_coulomb="0" mu_viscous="16"/>
    <limit lower="-1.7628" upper="1.7628" effort="87.0" velocity="2.175"/>
    <safety_controller k_position="100.0" soft_lower_limit="-1.7628" soft_upper_limit="1.7628" k_velocity="40.0"/>
    <origin xyz="0.0 0.0 0.0" rpy="-1.5707963267948966 0.0 0.0"/>
  </joint>
  <joint name="panda_link3_sc_joint" type="fixed">
    <parent link="panda_link3"/>
    <child link="panda_link3_sc"/>
    <axis xyz="1.0 0.0 0.0"/>
    <origin xyz="0.0 0.0 0.0" rpy="0.0 0.0 0.0"/>
  </joint>
  <joint name="panda_joint3" type="revolute">
    <parent link="panda_link2"/>
    <child link="panda_link3"/>
    <axis xyz="0.0 0.0 1.0"/>
    <dynamics damping="0.003" friction="0.0" D="1" K="7000" mu_coulomb="0" mu_viscous="16"/>
    <limit lower="-2.8973" upper="2.8973" effort="87.0" velocity="2.175"/>
    <safety_controller k_position="100.0" soft_lower_limit="-2.8973" soft_upper_limit="2.8973" k_velocity="40.0"/>
    <origin xyz="0.0 -0.316 0.0" rpy="1.5707963267948966 0.0 0.0"/>
  </joint>
  <joint name="panda_link4_sc_joint" type="fixed">
    <parent link="panda_link4"/>
    <child link="panda_link4_sc"/>
    <axis xyz="1.0 0.0 0.0"/>
    <origin xyz="0.0 0.0 0.0" rpy="0.0 0.0 0.0"/>
  </joint>
  <joint name="panda_joint4" type="revolute">
    <parent link="panda_link3"/>
    <child link="panda_link4"/>
    <axis xyz="0.0 0.0 1.0"/>
    <dynamics damping="0.003" friction="0.0" D="1" K="7000" mu_coulomb="0" mu_viscous="16"/>
    <limit lower="-3.0718" upper="-0.0698" effort="87.0" velocity="2.175"/>
    <safety_controller k_position="100.0" soft_lower_limit="-3.0718" soft_upper_limit="-0.0698" k_velocity="40.0"/>
    <origin xyz="0.0825 0.0 0.0" rpy="1.5707963267948966 0.0 0.0"/>
  </joint>
  <joint name="panda_link5_sc_joint" type="fixed">
    <parent link="panda_link5"/>
    <child link="panda_link5_sc"/>
    <axis xyz="1.0 0.0 0.0"/>
    <origin xyz="0.0 0.0 0.0" rpy="0.0 0.0 0.0"/>
  </joint>
  <joint name="panda_joint5" type="revolute">
    <parent link="panda_link4"/>
    <child link="panda_link5"/>
    <axis xyz="0.0 0.0 1.0"/>
    <dynamics damping="0.003" friction="0.0" D="1" K="7000" mu_coulomb="0" mu_viscous="16"/>
    <limit lower="-2.8973" upper="2.8973" effort="12.0" velocity="2.61"/>
    <safety_controller k_position="100.0" soft_lower_limit="-2.8973" soft_upper_limit="2.8973" k_velocity="40.0"/>
    <origin xyz="-0.0825 0.384 0.0" rpy="-1.5707963267948966 0.0 0.0"/>
  </joint>
  <joint name="panda_link6_sc_joint" type="fixed">
    <parent link="panda_link6"/>
    <child link="panda_link6_sc"/>
    <axis xyz="1.0 0.0 0.0"/>
    <origin xyz="0.0 0.0 0.0" rpy="0.0 0.0 0.0"/>
  </joint>
  <joint name="panda_joint6" type="revolute">
    <parent link="panda_link5"/>
    <child link="panda_link6"/>
    <axis xyz="0.0 0.0 1.0"/>
    <dynamics damping="0.003" friction="0.0" D="1" K="7000" mu_coulomb="0" mu_viscous="16"/>
    <limit lower="-0.0175" upper="3.7525" effort="12.0" velocity="2.61"/>
    <safety_controller k_position="100.0" soft_lower_limit="-0.0175" soft_upper_limit="3.7525" k_velocity="40.0"/>
    <origin xyz="0.0 0.0 0.0" rpy="1.5707963267948966 0.0 0.0"/>
  </joint>
  <joint name="panda_link7_sc_joint" type="fixed">
    <parent link="panda_link7"/>
    <child link="panda_link7_sc"/>
    <axis xyz="1.0 0.0 0.0"/>
    <origin xyz="0.0 0.0 0.0" rpy="0.0 0.0 0.7853981633974483"/>
  </joint>
  <joint name="panda_joint7" type="revolute">
    <parent link="panda_link6"/>
    <child link="panda_link7"/>
    <axis xyz="0.0 0.0 1.0"/>
    <dynamics damping="0.003" friction="0.0" D="1" K="7000" mu_coulomb="0" mu_viscous="16"/>
    <limit lower="-2.8973" upper="2.8973" effort="12.0" velocity="2.61"/>
    <safety_controller k_position="100.0" soft_lower_limit="-2.8973" soft_upper_limit="2.8973" k_velocity="40.0"/>
    <origin xyz="0.088 0.0 0.0" rpy="1.5707963267948966 0.0 0.0"/>
  </joint>
  <joint name="panda_joint8" type="fixed">
    <parent link="panda_link7"/>
    <child link="panda_link8"/>
    <axis xyz="1.0 0.0 0.0"/>
    <origin xyz="0.0 0.0 0.107" rpy="0.0 0.0 0.0"/>
  </joint>
  <joint name="panda_hand_joint" type="fixed">
    <parent link="panda_link8"/>
    <child link="panda_hand"/>
    <axis xyz="1.0 0.0 0.0"/>
    <origin xyz="0.0 0.0 0.0" rpy="0.0 0.0 -0.7853981633974483"/>
  </joint>
  <joint name="panda_hand_sc_joint" type="fixed">
    <parent link="panda_hand"/>
    <child link="panda_hand_sc"/>
    <axis xyz="1.0 0.0 0.0"/>
    <origin xyz="0.0 0.0 0.0" rpy="0.0 0.0 0.0"/>
  </joint>
  <joint name="panda_hand_tcp_joint" type="fixed">
    <parent link="panda_hand"/>
    <child link="panda_hand_tcp"/>
    <axis xyz="1.0 0.0 0.0"/>
    <origin xyz="0.0 0.0 0.1034" rpy="0.0 0.0 0.0"/>
  </joint>
  <joint name="panda_finger_joint1" type="prismatic">
    <parent link="panda_hand"/>
    <child link="panda_leftfinger"/>
    <axis xyz="0.0 1.0 0.0"/>
    <dynamics damping="0.3" friction="0.0"/>
    <limit upper="0.04" effort="100.0" velocity="0.2"/>
    <origin xyz="0.0 0.0 0.0584" rpy="0.0 0.0 0.0"/>
  </joint>
  <joint name="panda_finger_joint2" type="prismatic">
    <parent link="panda_hand"/>
    <child link="panda_rightfinger"/>
    <axis xyz="0.0 -1.0 0.0"/>
    <dynamics damping="0.3" friction="0.0"/>
    <limit upper="0.04" effort="100.0" velocity="0.2"/>
    <mimic joint="panda_finger_joint1"/>
    <origin xyz="0.0 0.0 0.0584" rpy="0.0 0.0 0.0"/>
  </joint>
</robot>
